Workbook

Sheet d02
F1: Part 1 | G1: Part 2
F2: =SUM(F4:F103) -> 2683 | G2: =SUM(G4:G103) -> 49710
A4: =input!$B1 -> 1 | B4: ='r'!AM3 -> 3 | C4: =g!AM3 -> 6 | D4: =b!AM3 -> 5 | E4: =AND($B4<=12,$C4<=13,$D4<=14) -> TRUE | F4: =IF(E4,A4,0) -> 1 | G4: =B4*C4*D4 -> 90
A5: =input!$B2 -> 2 | B5: ='r'!AM4 -> 9 | C5: =g!AM4 -> 13 | D5: =b!AM4 -> 2 | E5: =AND($B5<=12,$C5<=13,$D5<=14) -> TRUE | F5: =IF(E5,A5,0) -> 2 | G5: =B5*C5*D5 -> 234
A6: =input!$B3 -> 3 | B6: ='r'!AM5 -> 9 | C6: =g!AM5 -> 2 | D6: =b!AM5 -> 4 | E6: =AND($B6<=12,$C6<=13,$D6<=14) -> TRUE | F6: =IF(E6,A6,0) -> 3 | G6: =B6*C6*D6 -> 72
A7: =input!$B4 -> 4 | B7: ='r'!AM6 -> 11 | C7: =g!AM6 -> 4 | D7: =b!AM6 -> 18 | E7: =AND($B7<=12,$C7<=13,$D7<=14) -> FALSE | F7: =IF(E7,A7,0) -> 0 | G7: =B7*C7*D7 -> 792
A8: =input!$B5 -> 5 | B8: ='r'!AM7 -> 16 | C8: =g!AM7 -> 6 | D8: =b!AM7 -> 1 | E8: =AND($B8<=12,$C8<=13,$D8<=14) -> FALSE | F8: =IF(E8,A8,0) -> 0 | G8: =B8*C8*D8 -> 96
A9: =input!$B6 -> 6 | B9: ='r'!AM8 -> 9 | C9: =g!AM8 -> 19 | D9: =b!AM8 -> 6 | E9: =AND($B9<=12,$C9<=13,$D9<=14) -> FALSE | F9: =IF(E9,A9,0) -> 0 | G9: =B9*C9*D9 -> 1026
A10: =input!$B7 -> 7 | B10: ='r'!AM9 -> 6 | C10: =g!AM9 -> 9 | D10: =b!AM9 -> 16 | E10: =AND($B10<=12,$C10<=13,$D10<=14) -> FALSE | F10: =IF(E10,A10,0) -> 0 | G10: =B10*C10*D10 -> 864
A11: =input!$B8 -> 8 | B11: ='r'!AM10 -> 10 | C11: =g!AM10 -> 6 | D11: =b!AM10 -> 17 | E11: =AND($B11<=12,$C11<=13,$D11<=14) -> FALSE | F11: =IF(E11,A11,0) -> 0 | G11: =B11*C11*D11 -> 1020
A12: =input!$B9 -> 9 | B12: ='r'!AM11 -> 3 | C12: =g!AM11 -> 4 | D12: =b!AM11 -> 6 | E12: =AND($B12<=12,$C12<=13,$D12<=14) -> TRUE | F12: =IF(E12,A12,0) -> 9 | G12: =B12*C12*D12 -> 72
A13: =input!$B10 -> 10 | B13: ='r'!AM12 -> 10 | C13: =g!AM12 -> 5 | D13: =b!AM12 -> 6 | E13: =AND($B13<=12,$C13<=13,$D13<=14) -> TRUE | F13: =IF(E13,A13,0) -> 10 | G13: =B13*C13*D13 -> 300
A14: =input!$B11 -> 11 | B14: ='r'!AM13 -> 13 | C14: =g!AM13 -> 12 | D14: =b!AM13 -> 2 | E14: =AND($B14<=12,$C14<=13,$D14<=14) -> FALSE | F14: =IF(E14,A14,0) -> 0 | G14: =B14*C14*D14 -> 312
A15: =input!$B12 -> 12 | B15: ='r'!AM14 -> 3 | C15: =g!AM14 -> 3 | D15: =b!AM14 -> 11 | E15: =AND($B15<=12,$C15<=13,$D15<=14) -> TRUE | F15: =IF(E15,A15,0) -> 12 | G15: =B15*C15*D15 -> 99
... A103: =input!$B100 -> 100 | B103: ='r'!AM102 -> 6 | C103: =g!AM102 -> 6 | D103: =b!AM102 -> 14 | E103: =AND($B103<=12,$C103<=13,$D103<=14) -> TRUE | F103: =IF(E103,A103,0) -> 100 | G103: =B103*C103*D103 -> 504

Sheet r
A1: r
A3: =IF(LEFT(input!D1,1)=$A$1,input!C1,0) -> 0 | B3: =IF(LEFT(input!E1,1)=$A$1,input!D1,0) -> 0 | C3: =IF(LEFT(input!F1,1)=$A$1,input!E1,0) -> 0 | D3: =IF(LEFT(input!G1,1)=$A$1,input!F1,0) -> 0 | E3: =IF(LEFT(input!H1,1)=$A$1,input!G1,0) -> 3 | F3: =IF(LEFT(input!I1,1)=$A$1,input!H1,0) -> 0 | G3: =IF(LEFT(input!J1,1)=$A$1,input!I1,0) -> 0 | H3: =IF(LEFT(input!K1,1)=$A$1,input!J1,0) -> 0 | ... AI3: =IF(LEFT(input!AL1,1)=$A$1,input!AK1,0) -> 0 | AJ3: =IF(LEFT(input!AM3,1)=$A$1,input!AL1,0) -> 0 | AK3: =IF(LEFT(input!AN3,1)=$A$1,input!AM3,0) -> 0 | AL3: =IF(LEFT(input!AO3,1)=$A$1,input!AN3,0) -> 0 | AM3: =MAX(A3:AL3) -> 3
A4: =IF(LEFT(input!D2,1)=$A$1,input!C2,0) -> 2 | B4: =IF(LEFT(input!E2,1)=$A$1,input!D2,0) -> 0 | C4: =IF(LEFT(input!F2,1)=$A$1,input!E2,0) -> 0 | D4: =IF(LEFT(input!G2,1)=$A$1,input!F2,0) -> 0 | E4: =IF(LEFT(input!H2,1)=$A$1,input!G2,0) -> 0 | F4: =IF(LEFT(input!I2,1)=$A$1,input!H2,0) -> 0 | G4: =IF(LEFT(input!J2,1)=$A$1,input!I2,0) -> 0 | H4: =IF(LEFT(input!K2,1)=$A$1,input!J2,0) -> 0 | ... AI4: =IF(LEFT(input!AL2,1)=$A$1,input!AK2,0) -> 0 | AJ4: =IF(LEFT(input!AM4,1)=$A$1,input!AL2,0) -> 0 | AK4: =IF(LEFT(input!AN4,1)=$A$1,input!AM4,0) -> 0 | AL4: =IF(LEFT(input!AO4,1)=$A$1,input!AN4,0) -> 0 | AM4: =MAX(A4:AL4) -> 9
A5: =IF(LEFT(input!D3,1)=$A$1,input!C3,0) -> 0 | B5: =IF(LEFT(input!E3,1)=$A$1,input!D3,0) -> 0 | C5: =IF(LEFT(input!F3,1)=$A$1,input!E3,0) -> 0 | D5: =IF(LEFT(input!G3,1)=$A$1,input!F3,0) -> 0 | E5: =IF(LEFT(input!H3,1)=$A$1,input!G3,0) -> 9 | F5: =IF(LEFT(input!I3,1)=$A$1,input!H3,0) -> 0 | G5: =IF(LEFT(input!J3,1)=$A$1,input!I3,0) -> 3 | H5: =IF(LEFT(input!K3,1)=$A$1,input!J3,0) -> 0 | ... AI5: =IF(LEFT(input!AL3,1)=$A$1,input!AK3,0) -> 0 | AJ5: =IF(LEFT(input!AM5,1)=$A$1,input!AL3,0) -> 0 | AK5: =IF(LEFT(input!AN5,1)=$A$1,input!AM5,0) -> 0 | AL5: =IF(LEFT(input!AO5,1)=$A$1,input!AN5,0) -> 0 | AM5: =MAX(A5:AL5) -> 9
A6: =IF(LEFT(input!D4,1)=$A$1,input!C4,0) -> 9 | B6: =IF(LEFT(input!E4,1)=$A$1,input!D4,0) -> 0 | C6: =IF(LEFT(input!F4,1)=$A$1,input!E4,0) -> 0 | D6: =IF(LEFT(input!G4,1)=$A$1,input!F4,0) -> 0 | E6: =IF(LEFT(input!H4,1)=$A$1,input!G4,0) -> 0 | F6: =IF(LEFT(input!I4,1)=$A$1,input!H4,0) -> 0 | G6: =IF(LEFT(input!J4,1)=$A$1,input!I4,0) -> 8 | H6: =IF(LEFT(input!K4,1)=$A$1,input!J4,0) -> 0 | ... AI6: =IF(LEFT(input!AL4,1)=$A$1,input!AK4,0) -> 0 | AJ6: =IF(LEFT(input!AM6,1)=$A$1,input!AL4,0) -> 0 | AK6: =IF(LEFT(input!AN6,1)=$A$1,input!AM6,0) -> 0 | AL6: =IF(LEFT(input!AO6,1)=$A$1,input!AN6,0) -> 0 | AM6: =MAX(A6:AL6) -> 11
A7: =IF(LEFT(input!D5,1)=$A$1,input!C5,0) -> 0 | B7: =IF(LEFT(input!E5,1)=$A$1,input!D5,0) -> 0 | C7: =IF(LEFT(input!F5,1)=$A$1,input!E5,0) -> 0 | D7: =IF(LEFT(input!G5,1)=$A$1,input!F5,0) -> 0 | E7: =IF(LEFT(input!H5,1)=$A$1,input!G5,0) -> 3 | F7: =IF(LEFT(input!I5,1)=$A$1,input!H5,0) -> 0 | G7: =IF(LEFT(input!J5,1)=$A$1,input!I5,0) -> 16 | H7: =IF(LEFT(input!K5,1)=$A$1,input!J5,0) -> 0 | ... AI7: =IF(LEFT(input!AL5,1)=$A$1,input!AK5,0) -> 0 | AJ7: =IF(LEFT(input!AM7,1)=$A$1,input!AL5,0) -> 0 | AK7: =IF(LEFT(input!AN7,1)=$A$1,input!AM7,0) -> 0 | AL7: =IF(LEFT(input!AO7,1)=$A$1,input!AN7,0) -> 0 | AM7: =MAX(A7:AL7) -> 16
A8: =IF(LEFT(input!D6,1)=$A$1,input!C6,0) -> 0 | B8: =IF(LEFT(input!E6,1)=$A$1,input!D6,0) -> 0 | C8: =IF(LEFT(input!F6,1)=$A$1,input!E6,0) -> 7 | D8: =IF(LEFT(input!G6,1)=$A$1,input!F6,0) -> 0 | E8: =IF(LEFT(input!H6,1)=$A$1,input!G6,0) -> 0 | F8: =IF(LEFT(input!I6,1)=$A$1,input!H6,0) -> 0 | G8: =IF(LEFT(input!J6,1)=$A$1,input!I6,0) -> 0 | H8: =IF(LEFT(input!K6,1)=$A$1,input!J6,0) -> 0 | ... AI8: =IF(LEFT(input!AL6,1)=$A$1,input!AK6,0) -> 0 | AJ8: =IF(LEFT(input!AM8,1)=$A$1,input!AL6,0) -> 0 | AK8: =IF(LEFT(input!AN8,1)=$A$1,input!AM8,0) -> 0 | AL8: =IF(LEFT(input!AO8,1)=$A$1,input!AN8,0) -> 0 | AM8: =MAX(A8:AL8) -> 9
A9: =IF(LEFT(input!D7,1)=$A$1,input!C7,0) -> 0 | B9: =IF(LEFT(input!E7,1)=$A$1,input!D7,0) -> 0 | C9: =IF(LEFT(input!F7,1)=$A$1,input!E7,0) -> 0 | D9: =IF(LEFT(input!G7,1)=$A$1,input!F7,0) -> 0 | E9: =IF(LEFT(input!H7,1)=$A$1,input!G7,0) -> 6 | F9: =IF(LEFT(input!I7,1)=$A$1,input!H7,0) -> 0 | G9: =IF(LEFT(input!J7,1)=$A$1,input!I7,0) -> 0 | H9: =IF(LEFT(input!K7,1)=$A$1,input!J7,0) -> 0 | ... AI9: =IF(LEFT(input!AL7,1)=$A$1,input!AK7,0) -> 0 | AJ9: =IF(LEFT(input!AM9,1)=$A$1,input!AL7,0) -> 0 | AK9: =IF(LEFT(input!AN9,1)=$A$1,input!AM9,0) -> 0 | AL9: =IF(LEFT(input!AO9,1)=$A$1,input!AN9,0) -> 0 | AM9: =MAX(A9:AL9) -> 6
A10: =IF(LEFT(input!D8,1)=$A$1,input!C8,0) -> 0 | B10: =IF(LEFT(input!E8,1)=$A$1,input!D8,0) -> 0 | C10: =IF(LEFT(input!F8,1)=$A$1,input!E8,0) -> 10 | D10: =IF(LEFT(input!G8,1)=$A$1,input!F8,0) -> 0 | E10: =IF(LEFT(input!H8,1)=$A$1,input!G8,0) -> 7 | F10: =IF(LEFT(input!I8,1)=$A$1,input!H8,0) -> 0 | G10: =IF(LEFT(input!J8,1)=$A$1,input!I8,0) -> 0 | H10: =IF(LEFT(input!K8,1)=$A$1,input!J8,0) -> 0 | ... AI10: =IF(LEFT(input!AL8,1)=$A$1,input!AK8,0) -> 0 | AJ10: =IF(LEFT(input!AM10,1)=$A$1,input!AL8,0) -> 0 | AK10: =IF(LEFT(input!AN10,1)=$A$1,input!AM10,0) -> 0 | AL10: =IF(LEFT(input!AO10,1)=$A$1,input!AN10,0) -> 0 | AM10: =MAX(A10:AL10) -> 10
A11: =IF(LEFT(input!D9,1)=$A$1,input!C9,0) -> 2 | B11: =IF(LEFT(input!E9,1)=$A$1,input!D9,0) -> 0 | C11: =IF(LEFT(input!F9,1)=$A$1,input!E9,0) -> 0 | D11: =IF(LEFT(input!G9,1)=$A$1,input!F9,0) -> 0 | E11: =IF(LEFT(input!H9,1)=$A$1,input!G9,0) -> 0 | F11: =IF(LEFT(input!I9,1)=$A$1,input!H9,0) -> 0 | G11: =IF(LEFT(input!J9,1)=$A$1,input!I9,0) -> 0 | H11: =IF(LEFT(input!K9,1)=$A$1,input!J9,0) -> 0 | ... AI11: =IF(LEFT(input!AL9,1)=$A$1,input!AK9,0) -> 0 | AJ11: =IF(LEFT(input!AM11,1)=$A$1,input!AL9,0) -> 0 | AK11: =IF(LEFT(input!AN11,1)=$A$1,input!AM11,0) -> 0 | AL11: =IF(LEFT(input!AO11,1)=$A$1,input!AN11,0) -> 0 | AM11: =MAX(A11:AL11) -> 3
A12: =IF(LEFT(input!D10,1)=$A$1,input!C10,0) -> 0 | B12: =IF(LEFT(input!E10,1)=$A$1,input!D10,0) -> 0 | C12: =IF(LEFT(input!F10,1)=$A$1,input!E10,0) -> 5 | D12: =IF(LEFT(input!G10,1)=$A$1,input!F10,0) -> 0 | E12: =IF(LEFT(input!H10,1)=$A$1,input!G10,0) -> 0 | F12: =IF(LEFT(input!I10,1)=$A$1,input!H10,0) -> 0 | G12: =IF(LEFT(input!J10,1)=$A$1,input!I10,0) -> 0 | H12: =IF(LEFT(input!K10,1)=$A$1,input!J10,0) -> 0 | ... AI12: =IF(LEFT(input!AL10,1)=$A$1,input!AK10,0) -> 0 | AJ12: =IF(LEFT(input!AM12,1)=$A$1,input!AL10,0) -> 0 | AK12: =IF(LEFT(input!AN12,1)=$A$1,input!AM12,0) -> 0 | AL12: =IF(LEFT(input!AO12,1)=$A$1,input!AN12,0) -> 0 | AM12: =MAX(A12:AL12) -> 10
A13: =IF(LEFT(input!D11,1)=$A$1,input!C11,0) -> 0 | B13: =IF(LEFT(input!E11,1)=$A$1,input!D11,0) -> 0 | C13: =IF(LEFT(input!F11,1)=$A$1,input!E11,0) -> 7 | D13: =IF(LEFT(input!G11,1)=$A$1,input!F11,0) -> 0 | E13: =IF(LEFT(input!H11,1)=$A$1,input!G11,0) -> 0 | F13: =IF(LEFT(input!I11,1)=$A$1,input!H11,0) -> 0 | G13: =IF(LEFT(input!J11,1)=$A$1,input!I11,0) -> 0 | H13: =IF(LEFT(input!K11,1)=$A$1,input!J11,0) -> 0 | ... AI13: =IF(LEFT(input!AL11,1)=$A$1,input!AK11,0) -> 0 | AJ13: =IF(LEFT(input!AM13,1)=$A$1,input!AL11,0) -> 0 | AK13: =IF(LEFT(input!AN13,1)=$A$1,input!AM13,0) -> 0 | AL13: =IF(LEFT(input!AO13,1)=$A$1,input!AN13,0) -> 0 | AM13: =MAX(A13:AL13) -> 13
A14: =IF(LEFT(input!D12,1)=$A$1,input!C12,0) -> 0 | B14: =IF(LEFT(input!E12,1)=$A$1,input!D12,0) -> 0 | C14: =IF(LEFT(input!F12,1)=$A$1,input!E12,0) -> 2 | D14: =IF(LEFT(input!G12,1)=$A$1,input!F12,0) -> 0 | E14: =IF(LEFT(input!H12,1)=$A$1,input!G12,0) -> 0 | F14: =IF(LEFT(input!I12,1)=$A$1,input!H12,0) -> 0 | G14: =IF(LEFT(input!J12,1)=$A$1,input!I12,0) -> 0 | H14: =IF(LEFT(input!K12,1)=$A$1,input!J12,0) -> 0 | ... AI14: =IF(LEFT(input!AL12,1)=$A$1,input!AK12,0) -> 0 | AJ14: =IF(LEFT(input!AM14,1)=$A$1,input!AL12,0) -> 0 | AK14: =IF(LEFT(input!AN14,1)=$A$1,input!AM14,0) -> 0 | AL14: =IF(LEFT(input!AO14,1)=$A$1,input!AN14,0) -> 0 | AM14: =MAX(A14:AL14) -> 3
... A102: =IF(LEFT(input!D100,1)=$A$1,input!C100,0) -> 0 | B102: =IF(LEFT(input!E100,1)=$A$1,input!D100,0) -> 0 | C102: =IF(LEFT(input!F100,1)=$A$1,input!E100,0) -> 0 | D102: =IF(LEFT(input!G100,1)=$A$1,input!F100,0) -> 0 | E102: =IF(LEFT(input!H100,1)=$A$1,input!G100,0) -> 6 | F102: =IF(LEFT(input!I100,1)=$A$1,input!H100,0) -> 0 | G102: =IF(LEFT(input!J100,1)=$A$1,input!I100,0) -> 0 | H102: =IF(LEFT(input!K100,1)=$A$1,input!J100,0) -> 0 | ... AI102: =IF(LEFT(input!AL100,1)=$A$1,input!AK100,0) -> 0 | AJ102: =IF(LEFT(input!AM102,1)=$A$1,input!AL100,0) -> 0 | AK102: =IF(LEFT(input!AN102,1)=$A$1,input!AM102,0) -> 0 | AL102: =IF(LEFT(input!AO102,1)=$A$1,input!AN102,0) -> 0 | AM102: =MAX(A102:AL102) -> 6

Sheet g
A1: g
A3: =IF(LEFT(input!D1,1)=$A$1,input!C1,0) -> 6 | B3: =IF(LEFT(input!E1,1)=$A$1,input!D1,0) -> 0 | C3: =IF(LEFT(input!F1,1)=$A$1,input!E1,0) -> 0 | D3: =IF(LEFT(input!G1,1)=$A$1,input!F1,0) -> 0 | E3: =IF(LEFT(input!H1,1)=$A$1,input!G1,0) -> 0 | F3: =IF(LEFT(input!I1,1)=$A$1,input!H1,0) -> 0 | G3: =IF(LEFT(input!J1,1)=$A$1,input!I1,0) -> 1 | H3: =IF(LEFT(input!K1,1)=$A$1,input!J1,0) -> 0 | ... AI3: =IF(LEFT(input!AL1,1)=$A$1,input!AK1,0) -> 0 | AJ3: =IF(LEFT(input!AM3,1)=$A$1,input!AL1,0) -> 0 | AK3: =IF(LEFT(input!AN3,1)=$A$1,input!AM3,0) -> 0 | AL3: =IF(LEFT(input!AO3,1)=$A$1,input!AN3,0) -> 0 | AM3: =MAX(A3:AL3) -> 6
A4: =IF(LEFT(input!D2,1)=$A$1,input!C2,0) -> 0 | B4: =IF(LEFT(input!E2,1)=$A$1,input!D2,0) -> 0 | C4: =IF(LEFT(input!F2,1)=$A$1,input!E2,0) -> 7 | D4: =IF(LEFT(input!G2,1)=$A$1,input!F2,0) -> 0 | E4: =IF(LEFT(input!H2,1)=$A$1,input!G2,0) -> 13 | F4: =IF(LEFT(input!I2,1)=$A$1,input!H2,0) -> 0 | G4: =IF(LEFT(input!J2,1)=$A$1,input!I2,0) -> 0 | H4: =IF(LEFT(input!K2,1)=$A$1,input!J2,0) -> 0 | ... AI4: =IF(LEFT(input!AL2,1)=$A$1,input!AK2,0) -> 0 | AJ4: =IF(LEFT(input!AM4,1)=$A$1,input!AL2,0) -> 0 | AK4: =IF(LEFT(input!AN4,1)=$A$1,input!AM4,0) -> 0 | AL4: =IF(LEFT(input!AO4,1)=$A$1,input!AN4,0) -> 0 | AM4: =MAX(A4:AL4) -> 13
A5: =IF(LEFT(input!D3,1)=$A$1,input!C3,0) -> 2 | B5: =IF(LEFT(input!E3,1)=$A$1,input!D3,0) -> 0 | C5: =IF(LEFT(input!F3,1)=$A$1,input!E3,0) -> 0 | D5: =IF(LEFT(input!G3,1)=$A$1,input!F3,0) -> 0 | E5: =IF(LEFT(input!H3,1)=$A$1,input!G3,0) -> 0 | F5: =IF(LEFT(input!I3,1)=$A$1,input!H3,0) -> 0 | G5: =IF(LEFT(input!J3,1)=$A$1,input!I3,0) -> 0 | H5: =IF(LEFT(input!K3,1)=$A$1,input!J3,0) -> 0 | ... AI5: =IF(LEFT(input!AL3,1)=$A$1,input!AK3,0) -> 0 | AJ5: =IF(LEFT(input!AM5,1)=$A$1,input!AL3,0) -> 0 | AK5: =IF(LEFT(input!AN5,1)=$A$1,input!AM5,0) -> 0 | AL5: =IF(LEFT(input!AO5,1)=$A$1,input!AN5,0) -> 0 | AM5: =MAX(A5:AL5) -> 2
A6: =IF(LEFT(input!D4,1)=$A$1,input!C4,0) -> 0 | B6: =IF(LEFT(input!E4,1)=$A$1,input!D4,0) -> 0 | C6: =IF(LEFT(input!F4,1)=$A$1,input!E4,0) -> 3 | D6: =IF(LEFT(input!G4,1)=$A$1,input!F4,0) -> 0 | E6: =IF(LEFT(input!H4,1)=$A$1,input!G4,0) -> 3 | F6: =IF(LEFT(input!I4,1)=$A$1,input!H4,0) -> 0 | G6: =IF(LEFT(input!J4,1)=$A$1,input!I4,0) -> 0 | H6: =IF(LEFT(input!K4,1)=$A$1,input!J4,0) -> 0 | ... AI6: =IF(LEFT(input!AL4,1)=$A$1,input!AK4,0) -> 0 | AJ6: =IF(LEFT(input!AM6,1)=$A$1,input!AL4,0) -> 0 | AK6: =IF(LEFT(input!AN6,1)=$A$1,input!AM6,0) -> 0 | AL6: =IF(LEFT(input!AO6,1)=$A$1,input!AN6,0) -> 0 | AM6: =MAX(A6:AL6) -> 4
A7: =IF(LEFT(input!D5,1)=$A$1,input!C5,0) -> 0 | B7: =IF(LEFT(input!E5,1)=$A$1,input!D5,0) -> 0 | C7: =IF(LEFT(input!F5,1)=$A$1,input!E5,0) -> 2 | D7: =IF(LEFT(input!G5,1)=$A$1,input!F5,0) -> 0 | E7: =IF(LEFT(input!H5,1)=$A$1,input!G5,0) -> 0 | F7: =IF(LEFT(input!I5,1)=$A$1,input!H5,0) -> 0 | G7: =IF(LEFT(input!J5,1)=$A$1,input!I5,0) -> 0 | H7: =IF(LEFT(input!K5,1)=$A$1,input!J5,0) -> 0 | ... AI7: =IF(LEFT(input!AL5,1)=$A$1,input!AK5,0) -> 0 | AJ7: =IF(LEFT(input!AM7,1)=$A$1,input!AL5,0) -> 0 | AK7: =IF(LEFT(input!AN7,1)=$A$1,input!AM7,0) -> 0 | AL7: =IF(LEFT(input!AO7,1)=$A$1,input!AN7,0) -> 0 | AM7: =MAX(A7:AL7) -> 6
A8: =IF(LEFT(input!D6,1)=$A$1,input!C6,0) -> 4 | B8: =IF(LEFT(input!E6,1)=$A$1,input!D6,0) -> 0 | C8: =IF(LEFT(input!F6,1)=$A$1,input!E6,0) -> 0 | D8: =IF(LEFT(input!G6,1)=$A$1,input!F6,0) -> 0 | E8: =IF(LEFT(input!H6,1)=$A$1,input!G6,0) -> 0 | F8: =IF(LEFT(input!I6,1)=$A$1,input!H6,0) -> 0 | G8: =IF(LEFT(input!J6,1)=$A$1,input!I6,0) -> 18 | H8: =IF(LEFT(input!K6,1)=$A$1,input!J6,0) -> 0 | ... AI8: =IF(LEFT(input!AL6,1)=$A$1,input!AK6,0) -> 10 | AJ8: =IF(LEFT(input!AM8,1)=$A$1,input!AL6,0) -> 0 | AK8: =IF(LEFT(input!AN8,1)=$A$1,input!AM8,0) -> 0 | AL8: =IF(LEFT(input!AO8,1)=$A$1,input!AN8,0) -> 0 | AM8: =MAX(A8:AL8) -> 19
A9: =IF(LEFT(input!D7,1)=$A$1,input!C7,0) -> 0 | B9: =IF(LEFT(input!E7,1)=$A$1,input!D7,0) -> 0 | C9: =IF(LEFT(input!F7,1)=$A$1,input!E7,0) -> 5 | D9: =IF(LEFT(input!G7,1)=$A$1,input!F7,0) -> 0 | E9: =IF(LEFT(input!H7,1)=$A$1,input!G7,0) -> 0 | F9: =IF(LEFT(input!I7,1)=$A$1,input!H7,0) -> 0 | G9: =IF(LEFT(input!J7,1)=$A$1,input!I7,0) -> 0 | H9: =IF(LEFT(input!K7,1)=$A$1,input!J7,0) -> 0 | ... AI9: =IF(LEFT(input!AL7,1)=$A$1,input!AK7,0) -> 0 | AJ9: =IF(LEFT(input!AM9,1)=$A$1,input!AL7,0) -> 0 | AK9: =IF(LEFT(input!AN9,1)=$A$1,input!AM9,0) -> 0 | AL9: =IF(LEFT(input!AO9,1)=$A$1,input!AN9,0) -> 0 | AM9: =MAX(A9:AL9) -> 9
A10: =IF(LEFT(input!D8,1)=$A$1,input!C8,0) -> 6 | B10: =IF(LEFT(input!E8,1)=$A$1,input!D8,0) -> 0 | C10: =IF(LEFT(input!F8,1)=$A$1,input!E8,0) -> 0 | D10: =IF(LEFT(input!G8,1)=$A$1,input!F8,0) -> 0 | E10: =IF(LEFT(input!H8,1)=$A$1,input!G8,0) -> 0 | F10: =IF(LEFT(input!I8,1)=$A$1,input!H8,0) -> 0 | G10: =IF(LEFT(input!J8,1)=$A$1,input!I8,0) -> 6 | H10: =IF(LEFT(input!K8,1)=$A$1,input!J8,0) -> 0 | ... AI10: =IF(LEFT(input!AL8,1)=$A$1,input!AK8,0) -> 0 | AJ10: =IF(LEFT(input!AM10,1)=$A$1,input!AL8,0) -> 0 | AK10: =IF(LEFT(input!AN10,1)=$A$1,input!AM10,0) -> 0 | AL10: =IF(LEFT(input!AO10,1)=$A$1,input!AN10,0) -> 0 | AM10: =MAX(A10:AL10) -> 6
A11: =IF(LEFT(input!D9,1)=$A$1,input!C9,0) -> 0 | B11: =IF(LEFT(input!E9,1)=$A$1,input!D9,0) -> 0 | C11: =IF(LEFT(input!F9,1)=$A$1,input!E9,0) -> 4 | D11: =IF(LEFT(input!G9,1)=$A$1,input!F9,0) -> 0 | E11: =IF(LEFT(input!H9,1)=$A$1,input!G9,0) -> 0 | F11: =IF(LEFT(input!I9,1)=$A$1,input!H9,0) -> 0 | G11: =IF(LEFT(input!J9,1)=$A$1,input!I9,0) -> 2 | H11: =IF(LEFT(input!K9,1)=$A$1,input!J9,0) -> 0 | ... AI11: =IF(LEFT(input!AL9,1)=$A$1,input!AK9,0) -> 0 | AJ11: =IF(LEFT(input!AM11,1)=$A$1,input!AL9,0) -> 0 | AK11: =IF(LEFT(input!AN11,1)=$A$1,input!AM11,0) -> 0 | AL11: =IF(LEFT(input!AO11,1)=$A$1,input!AN11,0) -> 0 | AM11: =MAX(A11:AL11) -> 4
A12: =IF(LEFT(input!D10,1)=$A$1,input!C10,0) -> 3 | B12: =IF(LEFT(input!E10,1)=$A$1,input!D10,0) -> 0 | C12: =IF(LEFT(input!F10,1)=$A$1,input!E10,0) -> 0 | D12: =IF(LEFT(input!G10,1)=$A$1,input!F10,0) -> 0 | E12: =IF(LEFT(input!H10,1)=$A$1,input!G10,0) -> 0 | F12: =IF(LEFT(input!I10,1)=$A$1,input!H10,0) -> 0 | G12: =IF(LEFT(input!J10,1)=$A$1,input!I10,0) -> 0 | H12: =IF(LEFT(input!K10,1)=$A$1,input!J10,0) -> 0 | ... AI12: =IF(LEFT(input!AL10,1)=$A$1,input!AK10,0) -> 0 | AJ12: =IF(LEFT(input!AM12,1)=$A$1,input!AL10,0) -> 0 | AK12: =IF(LEFT(input!AN12,1)=$A$1,input!AM12,0) -> 0 | AL12: =IF(LEFT(input!AO12,1)=$A$1,input!AN12,0) -> 0 | AM12: =MAX(A12:AL12) -> 5
A13: =IF(LEFT(input!D11,1)=$A$1,input!C11,0) -> 0 | B13: =IF(LEFT(input!E11,1)=$A$1,input!D11,0) -> 0 | C13: =IF(LEFT(input!F11,1)=$A$1,input!E11,0) -> 0 | D13: =IF(LEFT(input!G11,1)=$A$1,input!F11,0) -> 0 | E13: =IF(LEFT(input!H11,1)=$A$1,input!G11,0) -> 9 | F13: =IF(LEFT(input!I11,1)=$A$1,input!H11,0) -> 0 | G13: =IF(LEFT(input!J11,1)=$A$1,input!I11,0) -> 0 | H13: =IF(LEFT(input!K11,1)=$A$1,input!J11,0) -> 0 | ... AI13: =IF(LEFT(input!AL11,1)=$A$1,input!AK11,0) -> 0 | AJ13: =IF(LEFT(input!AM13,1)=$A$1,input!AL11,0) -> 0 | AK13: =IF(LEFT(input!AN13,1)=$A$1,input!AM13,0) -> 0 | AL13: =IF(LEFT(input!AO13,1)=$A$1,input!AN13,0) -> 0 | AM13: =MAX(A13:AL13) -> 12
A14: =IF(LEFT(input!D12,1)=$A$1,input!C12,0) -> 0 | B14: =IF(LEFT(input!E12,1)=$A$1,input!D12,0) -> 0 | C14: =IF(LEFT(input!F12,1)=$A$1,input!E12,0) -> 0 | D14: =IF(LEFT(input!G12,1)=$A$1,input!F12,0) -> 0 | E14: =IF(LEFT(input!H12,1)=$A$1,input!G12,0) -> 0 | F14: =IF(LEFT(input!I12,1)=$A$1,input!H12,0) -> 0 | G14: =IF(LEFT(input!J12,1)=$A$1,input!I12,0) -> 2 | H14: =IF(LEFT(input!K12,1)=$A$1,input!J12,0) -> 0 | ... AI14: =IF(LEFT(input!AL12,1)=$A$1,input!AK12,0) -> 0 | AJ14: =IF(LEFT(input!AM14,1)=$A$1,input!AL12,0) -> 0 | AK14: =IF(LEFT(input!AN14,1)=$A$1,input!AM14,0) -> 0 | AL14: =IF(LEFT(input!AO14,1)=$A$1,input!AN14,0) -> 0 | AM14: =MAX(A14:AL14) -> 3
... A102: =IF(LEFT(input!D100,1)=$A$1,input!C100,0) -> 5 | B102: =IF(LEFT(input!E100,1)=$A$1,input!D100,0) -> 0 | C102: =IF(LEFT(input!F100,1)=$A$1,input!E100,0) -> 0 | D102: =IF(LEFT(input!G100,1)=$A$1,input!F100,0) -> 0 | E102: =IF(LEFT(input!H100,1)=$A$1,input!G100,0) -> 0 | F102: =IF(LEFT(input!I100,1)=$A$1,input!H100,0) -> 0 | G102: =IF(LEFT(input!J100,1)=$A$1,input!I100,0) -> 5 | H102: =IF(LEFT(input!K100,1)=$A$1,input!J100,0) -> 0 | ... AI102: =IF(LEFT(input!AL100,1)=$A$1,input!AK100,0) -> 0 | AJ102: =IF(LEFT(input!AM102,1)=$A$1,input!AL100,0) -> 0 | AK102: =IF(LEFT(input!AN102,1)=$A$1,input!AM102,0) -> 0 | AL102: =IF(LEFT(input!AO102,1)=$A$1,input!AN102,0) -> 0 | AM102: =MAX(A102:AL102) -> 6

Sheet b
A1: b
A3: =IF(LEFT(input!D1,1)=$A$1,input!C1,0) -> 0 | B3: =IF(LEFT(input!E1,1)=$A$1,input!D1,0) -> 0 | C3: =IF(LEFT(input!F1,1)=$A$1,input!E1,0) -> 3 | D3: =IF(LEFT(input!G1,1)=$A$1,input!F1,0) -> 0 | E3: =IF(LEFT(input!H1,1)=$A$1,input!G1,0) -> 0 | F3: =IF(LEFT(input!I1,1)=$A$1,input!H1,0) -> 0 | G3: =IF(LEFT(input!J1,1)=$A$1,input!I1,0) -> 0 | H3: =IF(LEFT(input!K1,1)=$A$1,input!J1,0) -> 0 | ... AI3: =IF(LEFT(input!AL1,1)=$A$1,input!AK1,0) -> 0 | AJ3: =IF(LEFT(input!AM3,1)=$A$1,input!AL1,0) -> 0 | AK3: =IF(LEFT(input!AN3,1)=$A$1,input!AM3,0) -> 0 | AL3: =IF(LEFT(input!AO3,1)=$A$1,input!AN3,0) -> 0 | AM3: =MAX(A3:AL3) -> 5
A4: =IF(LEFT(input!D2,1)=$A$1,input!C2,0) -> 0 | B4: =IF(LEFT(input!E2,1)=$A$1,input!D2,0) -> 0 | C4: =IF(LEFT(input!F2,1)=$A$1,input!E2,0) -> 0 | D4: =IF(LEFT(input!G2,1)=$A$1,input!F2,0) -> 0 | E4: =IF(LEFT(input!H2,1)=$A$1,input!G2,0) -> 0 | F4: =IF(LEFT(input!I2,1)=$A$1,input!H2,0) -> 0 | G4: =IF(LEFT(input!J2,1)=$A$1,input!I2,0) -> 2 | H4: =IF(LEFT(input!K2,1)=$A$1,input!J2,0) -> 0 | ... AI4: =IF(LEFT(input!AL2,1)=$A$1,input!AK2,0) -> 0 | AJ4: =IF(LEFT(input!AM4,1)=$A$1,input!AL2,0) -> 0 | AK4: =IF(LEFT(input!AN4,1)=$A$1,input!AM4,0) -> 0 | AL4: =IF(LEFT(input!AO4,1)=$A$1,input!AN4,0) -> 0 | AM4: =MAX(A4:AL4) -> 2
A5: =IF(LEFT(input!D3,1)=$A$1,input!C3,0) -> 0 | B5: =IF(LEFT(input!E3,1)=$A$1,input!D3,0) -> 0 | C5: =IF(LEFT(input!F3,1)=$A$1,input!E3,0) -> 3 | D5: =IF(LEFT(input!G3,1)=$A$1,input!F3,0) -> 0 | E5: =IF(LEFT(input!H3,1)=$A$1,input!G3,0) -> 0 | F5: =IF(LEFT(input!I3,1)=$A$1,input!H3,0) -> 0 | G5: =IF(LEFT(input!J3,1)=$A$1,input!I3,0) -> 0 | H5: =IF(LEFT(input!K3,1)=$A$1,input!J3,0) -> 0 | ... AI5: =IF(LEFT(input!AL3,1)=$A$1,input!AK3,0) -> 0 | AJ5: =IF(LEFT(input!AM5,1)=$A$1,input!AL3,0) -> 0 | AK5: =IF(LEFT(input!AN5,1)=$A$1,input!AM5,0) -> 0 | AL5: =IF(LEFT(input!AO5,1)=$A$1,input!AN5,0) -> 0 | AM5: =MAX(A5:AL5) -> 4
A6: =IF(LEFT(input!D4,1)=$A$1,input!C4,0) -> 0 | B6: =IF(LEFT(input!E4,1)=$A$1,input!D4,0) -> 0 | C6: =IF(LEFT(input!F4,1)=$A$1,input!E4,0) -> 0 | D6: =IF(LEFT(input!G4,1)=$A$1,input!F4,0) -> 0 | E6: =IF(LEFT(input!H4,1)=$A$1,input!G4,0) -> 0 | F6: =IF(LEFT(input!I4,1)=$A$1,input!H4,0) -> 0 | G6: =IF(LEFT(input!J4,1)=$A$1,input!I4,0) -> 0 | H6: =IF(LEFT(input!K4,1)=$A$1,input!J4,0) -> 0 | ... AI6: =IF(LEFT(input!AL4,1)=$A$1,input!AK4,0) -> 0 | AJ6: =IF(LEFT(input!AM6,1)=$A$1,input!AL4,0) -> 0 | AK6: =IF(LEFT(input!AN6,1)=$A$1,input!AM6,0) -> 0 | AL6: =IF(LEFT(input!AO6,1)=$A$1,input!AN6,0) -> 0 | AM6: =MAX(A6:AL6) -> 18
A7: =IF(LEFT(input!D5,1)=$A$1,input!C5,0) -> 1 | B7: =IF(LEFT(input!E5,1)=$A$1,input!D5,0) -> 0 | C7: =IF(LEFT(input!F5,1)=$A$1,input!E5,0) -> 0 | D7: =IF(LEFT(input!G5,1)=$A$1,input!F5,0) -> 0 | E7: =IF(LEFT(input!H5,1)=$A$1,input!G5,0) -> 0 | F7: =IF(LEFT(input!I5,1)=$A$1,input!H5,0) -> 0 | G7: =IF(LEFT(input!J5,1)=$A$1,input!I5,0) -> 0 | H7: =IF(LEFT(input!K5,1)=$A$1,input!J5,0) -> 0 | ... AI7: =IF(LEFT(input!AL5,1)=$A$1,input!AK5,0) -> 0 | AJ7: =IF(LEFT(input!AM7,1)=$A$1,input!AL5,0) -> 0 | AK7: =IF(LEFT(input!AN7,1)=$A$1,input!AM7,0) -> 0 | AL7: =IF(LEFT(input!AO7,1)=$A$1,input!AN7,0) -> 0 | AM7: =MAX(A7:AL7) -> 1
A8: =IF(LEFT(input!D6,1)=$A$1,input!C6,0) -> 0 | B8: =IF(LEFT(input!E6,1)=$A$1,input!D6,0) -> 0 | C8: =IF(LEFT(input!F6,1)=$A$1,input!E6,0) -> 0 | D8: =IF(LEFT(input!G6,1)=$A$1,input!F6,0) -> 0 | E8: =IF(LEFT(input!H6,1)=$A$1,input!G6,0) -> 1 | F8: =IF(LEFT(input!I6,1)=$A$1,input!H6,0) -> 0 | G8: =IF(LEFT(input!J6,1)=$A$1,input!I6,0) -> 0 | H8: =IF(LEFT(input!K6,1)=$A$1,input!J6,0) -> 0 | ... AI8: =IF(LEFT(input!AL6,1)=$A$1,input!AK6,0) -> 0 | AJ8: =IF(LEFT(input!AM8,1)=$A$1,input!AL6,0) -> 0 | AK8: =IF(LEFT(input!AN8,1)=$A$1,input!AM8,0) -> 0 | AL8: =IF(LEFT(input!AO8,1)=$A$1,input!AN8,0) -> 0 | AM8: =MAX(A8:AL8) -> 6
A9: =IF(LEFT(input!D7,1)=$A$1,input!C7,0) -> 16 | B9: =IF(LEFT(input!E7,1)=$A$1,input!D7,0) -> 0 | C9: =IF(LEFT(input!F7,1)=$A$1,input!E7,0) -> 0 | D9: =IF(LEFT(input!G7,1)=$A$1,input!F7,0) -> 0 | E9: =IF(LEFT(input!H7,1)=$A$1,input!G7,0) -> 0 | F9: =IF(LEFT(input!I7,1)=$A$1,input!H7,0) -> 0 | G9: =IF(LEFT(input!J7,1)=$A$1,input!I7,0) -> 1 | H9: =IF(LEFT(input!K7,1)=$A$1,input!J7,0) -> 0 | ... AI9: =IF(LEFT(input!AL7,1)=$A$1,input!AK7,0) -> 0 | AJ9: =IF(LEFT(input!AM9,1)=$A$1,input!AL7,0) -> 0 | AK9: =IF(LEFT(input!AN9,1)=$A$1,input!AM9,0) -> 0 | AL9: =IF(LEFT(input!AO9,1)=$A$1,input!AN9,0) -> 0 | AM9: =MAX(A9:AL9) -> 16
A10: =IF(LEFT(input!D8,1)=$A$1,input!C8,0) -> 0 | B10: =IF(LEFT(input!E8,1)=$A$1,input!D8,0) -> 0 | C10: =IF(LEFT(input!F8,1)=$A$1,input!E8,0) -> 0 | D10: =IF(LEFT(input!G8,1)=$A$1,input!F8,0) -> 0 | E10: =IF(LEFT(input!H8,1)=$A$1,input!G8,0) -> 0 | F10: =IF(LEFT(input!I8,1)=$A$1,input!H8,0) -> 0 | G10: =IF(LEFT(input!J8,1)=$A$1,input!I8,0) -> 0 | H10: =IF(LEFT(input!K8,1)=$A$1,input!J8,0) -> 0 | ... AI10: =IF(LEFT(input!AL8,1)=$A$1,input!AK8,0) -> 0 | AJ10: =IF(LEFT(input!AM10,1)=$A$1,input!AL8,0) -> 0 | AK10: =IF(LEFT(input!AN10,1)=$A$1,input!AM10,0) -> 0 | AL10: =IF(LEFT(input!AO10,1)=$A$1,input!AN10,0) -> 0 | AM10: =MAX(A10:AL10) -> 17
A11: =IF(LEFT(input!D9,1)=$A$1,input!C9,0) -> 0 | B11: =IF(LEFT(input!E9,1)=$A$1,input!D9,0) -> 0 | C11: =IF(LEFT(input!F9,1)=$A$1,input!E9,0) -> 0 | D11: =IF(LEFT(input!G9,1)=$A$1,input!F9,0) -> 0 | E11: =IF(LEFT(input!H9,1)=$A$1,input!G9,0) -> 5 | F11: =IF(LEFT(input!I9,1)=$A$1,input!H9,0) -> 0 | G11: =IF(LEFT(input!J9,1)=$A$1,input!I9,0) -> 0 | H11: =IF(LEFT(input!K9,1)=$A$1,input!J9,0) -> 0 | ... AI11: =IF(LEFT(input!AL9,1)=$A$1,input!AK9,0) -> 0 | AJ11: =IF(LEFT(input!AM11,1)=$A$1,input!AL9,0) -> 0 | AK11: =IF(LEFT(input!AN11,1)=$A$1,input!AM11,0) -> 0 | AL11: =IF(LEFT(input!AO11,1)=$A$1,input!AN11,0) -> 0 | AM11: =MAX(A11:AL11) -> 6
A12: =IF(LEFT(input!D10,1)=$A$1,input!C10,0) -> 0 | B12: =IF(LEFT(input!E10,1)=$A$1,input!D10,0) -> 0 | C12: =IF(LEFT(input!F10,1)=$A$1,input!E10,0) -> 0 | D12: =IF(LEFT(input!G10,1)=$A$1,input!F10,0) -> 0 | E12: =IF(LEFT(input!H10,1)=$A$1,input!G10,0) -> 6 | F12: =IF(LEFT(input!I10,1)=$A$1,input!H10,0) -> 0 | G12: =IF(LEFT(input!J10,1)=$A$1,input!I10,0) -> 4 | H12: =IF(LEFT(input!K10,1)=$A$1,input!J10,0) -> 0 | ... AI12: =IF(LEFT(input!AL10,1)=$A$1,input!AK10,0) -> 0 | AJ12: =IF(LEFT(input!AM12,1)=$A$1,input!AL10,0) -> 0 | AK12: =IF(LEFT(input!AN12,1)=$A$1,input!AM12,0) -> 0 | AL12: =IF(LEFT(input!AO12,1)=$A$1,input!AN12,0) -> 0 | AM12: =MAX(A12:AL12) -> 6
A13: =IF(LEFT(input!D11,1)=$A$1,input!C11,0) -> 1 | B13: =IF(LEFT(input!E11,1)=$A$1,input!D11,0) -> 0 | C13: =IF(LEFT(input!F11,1)=$A$1,input!E11,0) -> 0 | D13: =IF(LEFT(input!G11,1)=$A$1,input!F11,0) -> 0 | E13: =IF(LEFT(input!H11,1)=$A$1,input!G11,0) -> 0 | F13: =IF(LEFT(input!I11,1)=$A$1,input!H11,0) -> 0 | G13: =IF(LEFT(input!J11,1)=$A$1,input!I11,0) -> 1 | H13: =IF(LEFT(input!K11,1)=$A$1,input!J11,0) -> 0 | ... AI13: =IF(LEFT(input!AL11,1)=$A$1,input!AK11,0) -> 0 | AJ13: =IF(LEFT(input!AM13,1)=$A$1,input!AL11,0) -> 0 | AK13: =IF(LEFT(input!AN13,1)=$A$1,input!AM13,0) -> 0 | AL13: =IF(LEFT(input!AO13,1)=$A$1,input!AN13,0) -> 0 | AM13: =MAX(A13:AL13) -> 2
A14: =IF(LEFT(input!D12,1)=$A$1,input!C12,0) -> 4 | B14: =IF(LEFT(input!E12,1)=$A$1,input!D12,0) -> 0 | C14: =IF(LEFT(input!F12,1)=$A$1,input!E12,0) -> 0 | D14: =IF(LEFT(input!G12,1)=$A$1,input!F12,0) -> 0 | E14: =IF(LEFT(input!H12,1)=$A$1,input!G12,0) -> 9 | F14: =IF(LEFT(input!I12,1)=$A$1,input!H12,0) -> 0 | G14: =IF(LEFT(input!J12,1)=$A$1,input!I12,0) -> 0 | H14: =IF(LEFT(input!K12,1)=$A$1,input!J12,0) -> 0 | ... AI14: =IF(LEFT(input!AL12,1)=$A$1,input!AK12,0) -> 0 | AJ14: =IF(LEFT(input!AM14,1)=$A$1,input!AL12,0) -> 0 | AK14: =IF(LEFT(input!AN14,1)=$A$1,input!AM14,0) -> 0 | AL14: =IF(LEFT(input!AO14,1)=$A$1,input!AN14,0) -> 0 | AM14: =MAX(A14:AL14) -> 11
... A102: =IF(LEFT(input!D100,1)=$A$1,input!C100,0) -> 0 | B102: =IF(LEFT(input!E100,1)=$A$1,input!D100,0) -> 0 | C102: =IF(LEFT(input!F100,1)=$A$1,input!E100,0) -> 11 | D102: =IF(LEFT(input!G100,1)=$A$1,input!F100,0) -> 0 | E102: =IF(LEFT(input!H100,1)=$A$1,input!G100,0) -> 0 | F102: =IF(LEFT(input!I100,1)=$A$1,input!H100,0) -> 0 | G102: =IF(LEFT(input!J100,1)=$A$1,input!I100,0) -> 0 | H102: =IF(LEFT(input!K100,1)=$A$1,input!J100,0) -> 0 | ... AI102: =IF(LEFT(input!AL100,1)=$A$1,input!AK100,0) -> 0 | AJ102: =IF(LEFT(input!AM102,1)=$A$1,input!AL100,0) -> 0 | AK102: =IF(LEFT(input!AN102,1)=$A$1,input!AM102,0) -> 0 | AL102: =IF(LEFT(input!AO102,1)=$A$1,input!AN102,0) -> 0 | AM102: =MAX(A102:AL102) -> 14

Sheet input
A1: Game | B1: 1 | C1: 6 | D1: green, | E1: 3 | F1: blue | G1: 3 | H1: red, | I1: 1 | J1: green | K1: 4 | L1: green, | M1: 3 | N1: red, | O1: 5 | P1: blue
A2: Game | B2: 2 | C2: 2 | D2: red, | E2: 7 | F2: green | G2: 13 | H2: green, | I2: 2 | J2: blue, | K2: 4 | L2: red | M2: 4 | N2: green, | O2: 5 | P2: red, | Q2: 1 | R2: blue | S2: 1 | T2: blue, | U2: 9 | V2: red, | W2: 1 | X2: green
A3: Game | B3: 3 | C3: 2 | D3: green, | E3: 3 | F3: blue, | G3: 9 | H3: red | I3: 3 | J3: red, | K3: 2 | L3: green | M3: 6 | N3: red, | O3: 4 | P3: blue | Q3: 6 | R3: red
A4: Game | B4: 4 | C4: 9 | D4: red, | E4: 3 | F4: green | G4: 3 | H4: green, | I4: 8 | J4: red, | K4: 6 | L4: blue | M4: 12 | N4: blue, | O4: 4 | P4: green, | Q4: 6 | R4: red | S4: 4 | T4: green, | U4: 18 | V4: blue, | W4: 11 | X4: red | Y4: 9 | Z4: blue, | AA4: 2 | AB4: green, | AC4: 3 | AD4: red | AE4: 14 | AF4: blue, | AG4: 7 | AH4: red
A5: Game | B5: 5 | C5: 1 | D5: blue, | E5: 2 | F5: green, | G5: 3 | H5: red | I5: 16 | J5: red, | K5: 6 | L5: green | M5: 6 | N5: green, | O5: 2 | P5: red | Q5: 9 | R5: red, | S5: 1 | T5: green
A6: Game | B6: 6 | C6: 4 | D6: green, | E6: 7 | F6: red, | G6: 1 | H6: blue | I6: 18 | J6: green, | K6: 6 | L6: blue, | M6: 7 | N6: red | O6: 1 | P6: blue, | Q6: 3 | R6: red, | S6: 9 | T6: green | U6: 9 | V6: red, | W6: 19 | X6: green, | Y6: 1 | Z6: blue | AA6: 7 | AB6: red, | AC6: 9 | AD6: green, | AE6: 4 | AF6: blue | AG6: 5 | AH6: red, | AI6: 5 | AJ6: blue, | AK6: 10 | AL6: green
A7: Game | B7: 7 | C7: 16 | D7: blue, | E7: 5 | F7: green, | G7: 6 | H7: red | I7: 1 | J7: blue, | K7: 6 | L7: red, | M7: 9 | N7: green | O7: 6 | P7: green, | Q7: 3 | R7: red, | S7: 2 | T7: blue | U7: 2 | V7: red, | W7: 12 | X7: blue, | Y7: 2 | Z7: green
A8: Game | B8: 8 | C8: 6 | D8: green, | E8: 10 | F8: red | G8: 7 | H8: red, | I8: 6 | J8: green, | K8: 17 | L8: blue | M8: 13 | N8: blue, | O8: 1 | P8: red
A9: Game | B9: 9 | C9: 2 | D9: red, | E9: 4 | F9: green, | G9: 5 | H9: blue | I9: 2 | J9: green, | K9: 5 | L9: blue | M9: 4 | N9: green, | O9: 1 | P9: blue | Q9: 3 | R9: green, | S9: 3 | T9: red, | U9: 6 | V9: blue | W9: 3 | X9: green
A10: Game | B10: 10 | C10: 3 | D10: green, | E10: 5 | F10: red, | G10: 6 | H10: blue | I10: 4 | J10: blue, | K10: 4 | L10: red, | M10: 5 | N10: green | O10: 5 | P10: green, | Q10: 9 | R10: red, | S10: 5 | T10: blue | U10: 4 | V10: green, | W10: 6 | X10: blue, | Y10: 10 | Z10: red
A11: Game | B11: 11 | C11: 1 | D11: blue, | E11: 7 | F11: red, | G11: 9 | H11: green | I11: 1 | J11: blue, | K11: 13 | L11: red, | M11: 7 | N11: green | O11: 5 | P11: red | Q11: 4 | R11: red, | S11: 7 | T11: green, | U11: 2 | V11: blue | W11: 7 | X11: green, | Y11: 12 | Z11: red | AA11: 13 | AB11: red, | AC11: 2 | AD11: blue, | AE11: 12 | AF11: green
A12: Game | B12: 12 | C12: 4 | D12: blue, | E12: 2 | F12: red | G12: 9 | H12: blue, | I12: 2 | J12: green, | K12: 3 | L12: red | M12: 8 | N12: blue, | O12: 1 | P12: green, | Q12: 1 | R12: red | S12: 2 | T12: red, | U12: 3 | V12: green, | W12: 11 | X12: blue
A13: Game | B13: 13 | C13: 6 | D13: red, | E13: 8 | F13: green, | G13: 2 | H13: blue | I13: 6 | J13: red, | K13: 7 | L13: green | M13: 3 | N13: green, | O13: 3 | P13: red | Q13: 2 | R13: blue | S13: 3 | T13: red, | U13: 5 | V13: green
A14: Game | B14: 14 | C14: 2 | D14: green, | E14: 11 | F14: blue, | G14: 1 | H14: red | I14: 5 | J14: blue, | K14: 1 | L14: red, | M14: 1 | N14: green | O14: 3 | P14: green, | Q14: 12 | R14: blue, | S14: 2 | T14: red
A15: Game | B15: 15 | C15: 4 | D15: blue, | E15: 6 | F15: red, | G15: 7 | H15: green | I15: 1 | J15: red, | K15: 2 | L15: blue, | M15: 5 | N15: green | O15: 6 | P15: red, | Q15: 3 | R15: green, | S15: 8 | T15: blue | U15: 7 | V15: green, | W15: 8 | X15: blue, | Y15: 4 | Z15: red
A16: Game | B16: 16 | C16: 2 | D16: red, | E16: 16 | F16: blue | G16: 2 | H16: green, | I16: 7 | J16: red | K16: 15 | L16: blue, | M16: 7 | N16: red | O16: 2 | P16: red, | Q16: 3 | R16: green, | S16: 3 | T16: blue | U16: 3 | V16: red, | W16: 1 | X16: green, | Y16: 4 | Z16: blue | AA16: 4 | AB16: blue, | AC16: 3 | AD16: green
A17: Game | B17: 17 | C17: 2 | D17: red, | E17: 3 | F17: green, | G17: 10 | H17: blue | I17: 9 | J17: red, | K17: 4 | L17: blue, | M17: 3 | N17: green | O17: 3 | P17: green, | Q17: 11 | R17: red, | S17: 6 | T17: blue
A18: Game | B18: 18 | C18: 1 | D18: red | E18: 6 | F18: green, | G18: 1 | H18: red, | I18: 9 | J18: blue | K18: 4 | L18: blue, | M18: 2 | N18: green | O18: 6 | P18: blue, | Q18: 10 | R18: green
A19: Game | B19: 19 | C19: 2 | D19: red, | E19: 9 | F19: green | G19: 2 | H19: red, | I19: 1 | J19: blue | K19: 5 | L19: blue, | M19: 12 | N19: green | O19: 5 | P19: green | Q19: 8 | R19: green, | S19: 2 | T19: red, | U19: 3 | V19: blue | W19: 1 | X19: red, | Y19: 11 | Z19: green
A20: Game | B20: 20 | C20: 3 | D20: green, | E20: 2 | F20: red, | G20: 7 | H20: blue | I20: 1 | J20: blue, | K20: 10 | L20: green | M20: 1 | N20: red, | O20: 14 | P20: blue, | Q20: 13 | R20: green | S20: 3 | T20: green, | U20: 19 | V20: blue, | W20: 4 | X20: red
A21: Game | B21: 21 | C21: 8 | D21: red, | E21: 10 | F21: blue, | G21: 8 | H21: green | I21: 2 | J21: red, | K21: 7 | L21: green, | M21: 18 | N21: blue | O21: 4 | P21: green, | Q21: 11 | R21: blue, | S21: 4 | T21: red | U21: 5 | V21: green, | W21: 3 | X21: blue, | Y21: 10 | Z21: red
A22: Game | B22: 22 | C22: 17 | D22: blue, | E22: 2 | F22: green, | G22: 2 | H22: red | I22: 8 | J22: red, | K22: 7 | L22: blue | M22: 1 | N22: red, | O22: 9 | P22: blue, | Q22: 1 | R22: green
A23: Game | B23: 23 | C23: 4 | D23: blue, | E23: 18 | F23: red, | G23: 4 | H23: green | I23: 3 | J23: blue, | K23: 7 | L23: red | M23: 11 | N23: red | O23: 3 | P23: blue, | Q23: 6 | R23: red | S23: 19 | T23: red
A24: Game | B24: 24 | C24: 10 | D24: red, | E24: 1 | F24: blue, | G24: 17 | H24: green | I24: 17 | J24: green, | K24: 6 | L24: red | M24: 14 | N24: green, | O24: 4 | P24: blue
A25: Game | B25: 25 | C25: 4 | D25: blue, | E25: 9 | F25: green, | G25: 4 | H25: red | I25: 3 | J25: green, | K25: 5 | L25: blue | M25: 5 | N25: blue, | O25: 8 | P25: green | Q25: 3 | R25: green, | S25: 3 | T25: blue, | U25: 1 | V25: red | W25: 10 | X25: green, | Y25: 1 | Z25: blue, | AA25: 4 | AB25: red | AC25: 2 | AD25: green, | AE25: 2 | AF25: blue, | AG25: 1 | AH25: red
A26: Game | B26: 26 | C26: 18 | D26: green, | E26: 3 | F26: red, | G26: 12 | H26: blue | I26: 2 | J26: red, | K26: 7 | L26: green | M26: 11 | N26: blue, | O26: 17 | P26: green | Q26: 12 | R26: green, | S26: 11 | T26: blue | U26: 12 | V26: green, | W26: 4 | X26: blue, | Y26: 3 | Z26: red
A27: Game | B27: 27 | C27: 1 | D27: red, | E27: 3 | F27: blue, | G27: 8 | H27: green | I27: 15 | J27: blue, | K27: 8 | L27: red, | M27: 4 | N27: green | O27: 6 | P27: red, | Q27: 9 | R27: blue | S27: 6 | T27: red, | U27: 12 | V27: blue, | W27: 9 | X27: green | Y27: 4 | Z27: red, | AA27: 7 | AB27: blue, | AC27: 15 | AD27: green
A28: Game | B28: 28 | C28: 1 | D28: red, | E28: 14 | F28: green | G28: 1 | H28: blue, | I28: 11 | J28: green | K28: 2 | L28: green | M28: 4 | N28: red, | O28: 6 | P28: green, | Q28: 1 | R28: blue
A29: Game | B29: 29 | C29: 1 | D29: green, | E29: 13 | F29: red | G29: 4 | H29: red, | I29: 16 | J29: green, | K29: 7 | L29: blue | M29: 2 | N29: red, | O29: 4 | P29: blue | Q29: 12 | R29: green, | S29: 8 | T29: blue, | U29: 4 | V29: red | W29: 2 | X29: red | Y29: 12 | Z29: red, | AA29: 5 | AB29: green
A30: Game | B30: 30 | C30: 3 | D30: green, | E30: 4 | F30: blue, | G30: 3 | H30: red | I30: 5 | J30: blue, | K30: 4 | L30: green, | M30: 7 | N30: red | O30: 5 | P30: blue, | Q30: 2 | R30: green, | S30: 2 | T30: red | U30: 3 | V30: red, | W30: 1 | X30: blue
A31: Game | B31: 31 | C31: 1 | D31: blue, | E31: 8 | F31: green | G31: 9 | H31: green, | I31: 2 | J31: blue, | K31: 1 | L31: red | M31: 1 | N31: red, | O31: 2 | P31: blue
A32: Game | B32: 32 | C32: 11 | D32: red, | E32: 5 | F32: green, | G32: 4 | H32: blue | I32: 3 | J32: blue, | K32: 11 | L32: red, | M32: 8 | N32: green | O32: 6 | P32: blue, | Q32: 3 | R32: green, | S32: 17 | T32: red | U32: 4 | V32: red, | W32: 7 | X32: green, | Y32: 10 | Z32: blue
A33: Game | B33: 33 | C33: 6 | D33: blue, | E33: 4 | F33: red | G33: 1 | H33: green | I33: 1 | J33: green, | K33: 4 | L33: red, | M33: 4 | N33: blue | O33: 1 | P33: green, | Q33: 3 | R33: red, | S33: 10 | T33: blue | U33: 10 | V33: blue, | W33: 1 | X33: red
A34: Game | B34: 34 | C34: 2 | D34: green, | E34: 3 | F34: blue, | G34: 3 | H34: red | I34: 4 | J34: red | K34: 2 | L34: red, | M34: 2 | N34: blue
A35: Game | B35: 35 | C35: 9 | D35: green, | E35: 13 | F35: blue | G35: 13 | H35: blue, | I35: 14 | J35: red, | K35: 1 | L35: green | M35: 11 | N35: blue, | O35: 4 | P35: red, | Q35: 7 | R35: green | S35: 5 | T35: blue, | U35: 5 | V35: red, | W35: 8 | X35: green | Y35: 4 | Z35: red, | AA35: 2 | AB35: blue, | AC35: 2 | AD35: green
A36: Game | B36: 36 | C36: 9 | D36: red, | E36: 5 | F36: blue, | G36: 8 | H36: green | I36: 7 | J36: red, | K36: 20 | L36: blue | M36: 6 | N36: green, | O36: 16 | P36: blue, | Q36: 5 | R36: red | S36: 12 | T36: red, | U36: 3 | V36: blue, | W36: 3 | X36: green | Y36: 3 | Z36: green, | AA36: 6 | AB36: blue, | AC36: 11 | AD36: red | AE36: 11 | AF36: red, | AG36: 8 | AH36: blue, | AI36: 3 | AJ36: green
A37: Game | B37: 37 | C37: 10 | D37: green, | E37: 11 | F37: red, | G37: 3 | H37: blue | I37: 2 | J37: blue, | K37: 6 | L37: green, | M37: 11 | N37: red | O37: 9 | P37: green, | Q37: 8 | R37: red, | S37: 2 | T37: blue
A38: Game | B38: 38 | C38: 2 | D38: red, | E38: 2 | F38: green, | G38: 4 | H38: blue | I38: 3 | J38: red, | K38: 4 | L38: green, | M38: 3 | N38: blue | O38: 8 | P38: green, | Q38: 1 | R38: blue, | S38: 1 | T38: red | U38: 3 | V38: red, | W38: 5 | X38: blue, | Y38: 5 | Z38: green
A39: Game | B39: 39 | C39: 3 | D39: green, | E39: 17 | F39: red, | G39: 4 | H39: blue | I39: 2 | J39: green, | K39: 20 | L39: red | M39: 4 | N39: blue, | O39: 4 | P39: red, | Q39: 5 | R39: green | S39: 5 | T39: blue, | U39: 7 | V39: green, | W39: 7 | X39: red | Y39: 4 | Z39: blue, | AA39: 5 | AB39: green, | AC39: 16 | AD39: red
A40: Game | B40: 40 | C40: 2 | D40: green, | E40: 2 | F40: blue, | G40: 4 | H40: red | I40: 3 | J40: blue, | K40: 16 | L40: green | M40: 1 | N40: green, | O40: 2 | P40: blue | Q40: 1 | R40: red | S40: 3 | T40: blue, | U40: 15 | V40: green | W40: 13 | X40: green, | Y40: 1 | Z40: red, | AA40: 2 | AB40: blue
...
